[ 2025-03-23 18:57:31,656 ] 248 django.request - ERROR - Internal Server Error: /edit/
Traceback (most recent call last):
  File "C:\Users\vivek\AppData\Local\Programs\Python\Python310\lib\site-packages\django\core\handlers\exception.py", line 55, in inner
    response = get_response(request)
  File "C:\Users\vivek\AppData\Local\Programs\Python\Python310\lib\site-packages\django\core\handlers\base.py", line 197, in _get_response
    response = wrapped_callback(request, *callback_args, **callback_kwargs)
  File "C:\Users\vivek\AppData\Local\Programs\Python\Python310\lib\site-packages\django\contrib\auth\decorators.py", line 60, in _view_wrapper
    return view_func(request, *args, **kwargs)
  File "C:\Users\vivek\Desktop\Projects\Cyber Guardia\Cyber-Bullying-Detection\accounts\views.py", line 161, in edit_profile
    return redirect('home', username=request.user.username)
  File "C:\Users\vivek\AppData\Local\Programs\Python\Python310\lib\site-packages\django\shortcuts.py", line 49, in redirect
    return redirect_class(resolve_url(to, *args, **kwargs))
  File "C:\Users\vivek\AppData\Local\Programs\Python\Python310\lib\site-packages\django\shortcuts.py", line 180, in resolve_url
    return reverse(to, args=args, kwargs=kwargs)
  File "C:\Users\vivek\AppData\Local\Programs\Python\Python310\lib\site-packages\django\urls\base.py", line 88, in reverse
    return resolver._reverse_with_prefix(view, prefix, *args, **kwargs)
  File "C:\Users\vivek\AppData\Local\Programs\Python\Python310\lib\site-packages\django\urls\resolvers.py", line 831, in _reverse_with_prefix
    raise NoReverseMatch(msg)
django.urls.exceptions.NoReverseMatch: Reverse for 'home' with keyword arguments '{'username': 'user'}' not found. 1 pattern(s) tried: ['posts/\\Z']
[ 2025-03-23 18:58:14,887 ] 266 django.utils.autoreload - INFO - C:\Users\vivek\Desktop\Projects\Cyber Guardia\Cyber-Bullying-Detection\accounts\views.py changed, reloading.
